Connecting...
Traceback (most recent call last):
  File "/Users/merlinhof/Desktop/vectorLaser/backend/./laser.py", line 25, in <module>
    line = ser.readline().decode('utf-8').strip()
  File "/Users/merlinhof/Library/Python/3.9/lib/python/site-packages/serial/serialposix.py", line 595, in read
    raise SerialException(
serial.serialutil.SerialException: device reports readiness to read but returned no data (device disconnected or multiple access on port?)
