Connecting...
Traceback (most recent call last):
  File "/Users/merlinhof/Library/Python/3.9/lib/python/site-packages/serial/serialposix.py", line 575, in read
    buf = os.read(self.fd, size - len(read))
OSError: [Errno 6] Device not configured

During handling of the above exception, another exception occurred:

Traceback (most recent call last):
  File "/Users/merlinhof/Desktop/vectorLaser/backend/./laser.py", line 25, in <module>
    line = ser.readline().decode('utf-8').strip()
  File "/Users/merlinhof/Library/Python/3.9/lib/python/site-packages/serial/serialposix.py", line 581, in read
    raise SerialException('read failed: {}'.format(e))
serial.serialutil.SerialException: read failed: [Errno 6] Device not configured
